Workbook

Sheet MGS5
A1: DATA | C1: KM TOTALI | D1: KM PARZIALI | E1: % PRIMA DELLA CARICA | F1: % DOPO LA CARICA | G1: % CARICATA | H1: KWh | I1: KWh EFFETTIVI | J1: KWh/ 100 KM | K1: PREZZO/ KWh | L1: COSTO | M1: COSTO MENSILE | N1: PROGRESSIVO CASA | O1: MESE | P1: DOVE
A2: =IF(ISNUMBER(B3),CHOOSE(MONTH(B3),"GENNAIO","FEBBRAIO","MARZO","APRILE","MAGGIO","GIUGNO","LUGLIO","AGOSTO","SETTEMBRE","OTTOBRE","NOVEMBRE","DICEMBRE")&" "&YEAR(B3),"") -> FEBBRAIO 2026 | O2: =IF(ISNUMBER(B3),CHOOSE(MONTH(B3),"GENNAIO","FEBBRAIO","MARZO","APRILE","MAGGIO","GIUGNO","LUGLIO","AGOSTO","SETTEMBRE","OTTOBRE","NOVEMBRE","DICEMBRE")&" "&YEAR(B3),"") -> FEBBRAIO 2026
B3: 46080 | C3: 286 | D3: =IF(C3="","",C3) -> 286 | E3: 0.26 | F3: 0.86 | G3: =IF(AND(E3="",F3=""),"",IF(OR(E3>1,F3>1),(F3-E3)/100,F3-E3)) -> 0.6 | H3: =IF(G3="","",64*G3) -> 38.4 | I3: 39.34 | J3: =IFERROR(IF(OR(D3="",D3=0),"",I3/D3*100),"") -> 13.755245 | K3: 0.2 | L3: =IF(I3="","",I3*K3) -> 7.868 | M3: =IF(B3="","",IFERROR(SUMPRODUCT(ISNUMBER(B$3:B3)*(MONTH(IF(ISNUMBER(B$3:B3),B$3:B3,1))=MONTH(B3))*(YEAR(IF(ISNUMBER(B$3:B3),B$3:B3,1))=YEAR(B3))*IF(ISNUMBER(L$3:L3),L$3:L3,0)),"")) -> 7.868 | N3: =IFERROR(SUMIF(P$3:P3,"CASA",L$3:L3),"") -> 7.868 | P3: =IF(K3=0.2,"CASA","") -> CASA
A4: =IF(ISNUMBER(B5),CHOOSE(MONTH(B5),"GENNAIO","FEBBRAIO","MARZO","APRILE","MAGGIO","GIUGNO","LUGLIO","AGOSTO","SETTEMBRE","OTTOBRE","NOVEMBRE","DICEMBRE")&" "&YEAR(B5),"") -> MARZO 2026 | O4: =IF(ISNUMBER(B5),CHOOSE(MONTH(B5),"GENNAIO","FEBBRAIO","MARZO","APRILE","MAGGIO","GIUGNO","LUGLIO","AGOSTO","SETTEMBRE","OTTOBRE","NOVEMBRE","DICEMBRE")&" "&YEAR(B5),"") -> MARZO 2026
B5: 46085 | C5: 533 | D5: =IF(C5="","",C5-IF(C4<>"",C4,IF(C3<>"",C3,IF(C2<>"",C2,0)))) -> 247 | E5: 0.14 | F5: 0.86 | G5: =IF(AND(E5="",F5=""),"",IF(OR(E5>1,F5>1),(F5-E5)/100,F5-E5)) -> 0.72 | H5: =IF(G5="","",64*G5) -> 46.08 | I5: 46.156 | J5: =IFERROR(IF(OR(D5="",D5=0),"",I5/D5*100),"") -> 18.68664 | K5: 0.2 | L5: =IF(I5="","",I5*K5) -> 9.2312 | M5: =IF(B5="","",IFERROR(SUMPRODUCT(ISNUMBER(B$3:B5)*(MONTH(IF(ISNUMBER(B$3:B5),B$3:B5,1))=MONTH(B5))*(YEAR(IF(ISNUMBER(B$3:B5),B$3:B5,1))=YEAR(B5))*IF(ISNUMBER(L$3:L5),L$3:L5,0)),"")) -> 9.2312 | N5: =IFERROR(SUMIF(P$3:P5,"CASA",L$3:L5),"") -> 17.0992 | P5: =IF(K5=0.2,"CASA","") -> CASA
B6: 46092 | C6: 758 | D6: =IF(C6="","",C6-IF(C5<>"",C5,IF(C4<>"",C4,IF(C3<>"",C3,0)))) -> 225 | E6: 0.18 | F6: 0.8 | G6: =IF(AND(E6="",F6=""),"",IF(OR(E6>1,F6>1),(F6-E6)/100,F6-E6)) -> 0.62 | H6: =IF(G6="","",64*G6) -> 39.68 | I6: 40.374 | J6: =IFERROR(IF(OR(D6="",D6=0),"",I6/D6*100),"") -> 17.944 | K6: 0.2 | L6: =IF(I6="","",I6*K6) -> 8.0748 | M6: =IF(B6="","",IFERROR(SUMPRODUCT(ISNUMBER(B$3:B6)*(MONTH(IF(ISNUMBER(B$3:B6),B$3:B6,1))=MONTH(B6))*(YEAR(IF(ISNUMBER(B$3:B6),B$3:B6,1))=YEAR(B6))*IF(ISNUMBER(L$3:L6),L$3:L6,0)),"")) -> 17.306 | N6: =IFERROR(SUMIF(P$3:P6,"CASA",L$3:L6),"") -> 25.174 | P6: =IF(K6=0.2,"CASA","") -> CASA
B7: 46097 | C7: 926 | D7: =IF(C7="","",C7-IF(C6<>"",C6,IF(C5<>"",C5,IF(C4<>"",C4,0)))) -> 168 | E7: 0.18 | F7: 0.8 | G7: =IF(AND(E7="",F7=""),"",IF(OR(E7>1,F7>1),(F7-E7)/100,F7-E7)) -> 0.62 | H7: =IF(G7="","",64*G7) -> 39.68 | I7: 30.54 | J7: =IFERROR(IF(OR(D7="",D7=0),"",I7/D7*100),"") -> 18.178571 | K7: 0.5 | L7: =IF(I7="","",I7*K7) -> 15.27 | M7: =IF(B7="","",IFERROR(SUMPRODUCT(ISNUMBER(B$3:B7)*(MONTH(IF(ISNUMBER(B$3:B7),B$3:B7,1))=MONTH(B7))*(YEAR(IF(ISNUMBER(B$3:B7),B$3:B7,1))=YEAR(B7))*IF(ISNUMBER(L$3:L7),L$3:L7,0)),"")) -> 32.576 | N7: =IFERROR(SUMIF(P$3:P7,"CASA",L$3:L7),"") -> 25.174 | P7: =IF(K7=0.2,"CASA","")
B8: 46101 | C8: 1130 | D8: =IF(C8="","",C8-IF(C7<>"",C7,IF(C6<>"",C6,IF(C5<>"",C5,0)))) -> 204 | E8: 0.3 | F8: 0.84 | G8: =IF(AND(E8="",F8=""),"",IF(OR(E8>1,F8>1),(F8-E8)/100,F8-E8)) -> 0.54 | H8: =IF(G8="","",64*G8) -> 34.56 | I8: 34.08 | J8: =IFERROR(IF(OR(D8="",D8=0),"",I8/D8*100),"") -> 16.705882 | K8: 0.5 | L8: =IF(I8="","",I8*K8) -> 17.04 | M8: =IF(B8="","",IFERROR(SUMPRODUCT(ISNUMBER(B$3:B8)*(MONTH(IF(ISNUMBER(B$3:B8),B$3:B8,1))=MONTH(B8))*(YEAR(IF(ISNUMBER(B$3:B8),B$3:B8,1))=YEAR(B8))*IF(ISNUMBER(L$3:L8),L$3:L8,0)),"")) -> 49.616 | N8: =IFERROR(SUMIF(P$3:P8,"CASA",L$3:L8),"") -> 25.174 | P8: =IF(K8=0.2,"CASA","")
B9: 46107 | C9: 1293 | D9: =IF(C9="","",C9-IF(C8<>"",C8,IF(C7<>"",C7,IF(C6<>"",C6,0)))) -> 163 | E9: 0.38 | F9: 0.76 | G9: =IF(AND(E9="",F9=""),"",IF(OR(E9>1,F9>1),(F9-E9)/100,F9-E9)) -> 0.38 | H9: =IF(G9="","",64*G9) -> 24.32 | I9: 23.79 | J9: =IFERROR(IF(OR(D9="",D9=0),"",I9/D9*100),"") -> 14.595092 | K9: 0.2 | L9: =IF(I9="","",I9*K9) -> 4.758 | M9: =IF(B9="","",IFERROR(SUMPRODUCT(ISNUMBER(B$3:B9)*(MONTH(IF(ISNUMBER(B$3:B9),B$3:B9,1))=MONTH(B9))*(YEAR(IF(ISNUMBER(B$3:B9),B$3:B9,1))=YEAR(B9))*IF(ISNUMBER(L$3:L9),L$3:L9,0)),"")) -> 54.374 | N9: =IFERROR(SUMIF(P$3:P9,"CASA",L$3:L9),"") -> 29.932 | P9: =IF(K9=0.2,"CASA","") -> CASA
B10: 46111 | C10: 1400 | D10: =IF(C10="","",C10-IF(C9<>"",C9,IF(C8<>"",C8,IF(C7<>"",C7,0)))) -> 107 | E10: 0.44 | F10: 0.8 | G10: =IF(AND(E10="",F10=""),"",IF(OR(E10>1,F10>1),(F10-E10)/100,F10-E10)) -> 0.36 | H10: =IF(G10="","",64*G10) -> 23.04 | I10: 24.04 | J10: =IFERROR(IF(OR(D10="",D10=0),"",I10/D10*100),"") -> 22.46729 | K10: 0.2 | L10: =IF(I10="","",I10*K10) -> 4.808 | M10: =IF(B10="","",IFERROR(SUMPRODUCT(ISNUMBER(B$3:B10)*(MONTH(IF(ISNUMBER(B$3:B10),B$3:B10,1))=MONTH(B10))*(YEAR(IF(ISNUMBER(B$3:B10),B$3:B10,1))=YEAR(B10))*IF(ISNUMBER(L$3:L10),L$3:L10,0)),"")) -> 59.182 | N10: =IFERROR(SUMIF(P$3:P10,"CASA",L$3:L10),"") -> 34.74 | P10: =IF(K10=0.2,"CASA","") -> CASA
A11: =IF(ISNUMBER(B12),CHOOSE(MONTH(B12),"GENNAIO","FEBBRAIO","MARZO","APRILE","MAGGIO","GIUGNO","LUGLIO","AGOSTO","SETTEMBRE","OTTOBRE","NOVEMBRE","DICEMBRE")&" "&YEAR(B12),"") -> APRILE 2026 | D11: =IF(C11="","",C11-IF(C10<>"",C10,IF(C9<>"",C9,IF(C8<>"",C8,0)))) | O11: =IF(ISNUMBER(B12),CHOOSE(MONTH(B12),"GENNAIO","FEBBRAIO","MARZO","APRILE","MAGGIO","GIUGNO","LUGLIO","AGOSTO","SETTEMBRE","OTTOBRE","NOVEMBRE","DICEMBRE")&" "&YEAR(B12),"") -> APRILE 2026
B12: 46113 | C12: 1543 | D12: =IF(C12="","",C12-IF(C11<>"",C11,IF(C10<>"",C10,IF(C9<>"",C9,0)))) -> 143 | E12: 0.34 | F12: 0.8 | G12: =IF(AND(E12="",F12=""),"",IF(OR(E12>1,F12>1),(F12-E12)/100,F12-E12)) -> 0.46 | H12: =IF(G12="","",64*G12) -> 29.44 | I12: 30.56 | J12: =IFERROR(IF(OR(D12="",D12=0),"",I12/D12*100),"") -> 21.370629 | K12: 0.2 | L12: =IF(I12="","",I12*K12) -> 6.112 | M12: =IF(B12="","",IFERROR(SUMPRODUCT(ISNUMBER(B$3:B12)*(MONTH(IF(ISNUMBER(B$3:B12),B$3:B12,1))=MONTH(B12))*(YEAR(IF(ISNUMBER(B$3:B12),B$3:B12,1))=YEAR(B12))*IF(ISNUMBER(L$3:L12),L$3:L12,0)),"")) -> 6.112 | N12: =IFERROR(SUMIF(P$3:P12,"CASA",L$3:L12),"") -> 40.852 | P12: =IF(K12=0.2,"CASA","") -> CASA
B13: 46117 | C13: 1717 | D13: =IF(C13="","",C13-IF(C12<>"",C12,IF(C11<>"",C11,IF(C10<>"",C10,0)))) -> 174 | E13: 0.33 | F13: 0.67 | G13: =IF(AND(E13="",F13=""),"",IF(OR(E13>1,F13>1),(F13-E13)/100,F13-E13)) -> 0.34 | H13: =IF(G13="","",64*G13) -> 21.76 | I13: 20.976 | J13: =IFERROR(IF(OR(D13="",D13=0),"",I13/D13*100),"") -> 12.055172 | K13: 0.2 | L13: =IF(I13="","",I13*K13) -> 4.1952 | M13: =IF(B13="","",IFERROR(SUMPRODUCT(ISNUMBER(B$3:B13)*(MONTH(IF(ISNUMBER(B$3:B13),B$3:B13,1))=MONTH(B13))*(YEAR(IF(ISNUMBER(B$3:B13),B$3:B13,1))=YEAR(B13))*IF(ISNUMBER(L$3:L13),L$3:L13,0)),"")) -> 10.3072 | N13: =IFERROR(SUMIF(P$3:P13,"CASA",L$3:L13),"") -> 45.0472 | P13: =IF(K13=0.2,"CASA","") -> CASA
B14: 46117 | C14: 1792 | D14: =IF(C14="","",C14-IF(C13<>"",C13,IF(C12<>"",C12,IF(C11<>"",C11,0)))) -> 75 | E14: 0.41 | F14: 0.8 | G14: =IF(AND(E14="",F14=""),"",IF(OR(E14>1,F14>1),(F14-E14)/100,F14-E14)) -> 0.39 | H14: =IF(G14="","",64*G14) -> 24.96 | I14: 25.307 | J14: =IFERROR(IF(OR(D14="",D14=0),"",I14/D14*100),"") -> 33.742667 | K14: 0.2 | L14: =IF(I14="","",I14*K14) -> 5.0614 | M14: =IF(B14="","",IFERROR(SUMPRODUCT(ISNUMBER(B$3:B14)*(MONTH(IF(ISNUMBER(B$3:B14),B$3:B14,1))=MONTH(B14))*(YEAR(IF(ISNUMBER(B$3:B14),B$3:B14,1))=YEAR(B14))*IF(ISNUMBER(L$3:L14),L$3:L14,0)),"")) -> 15.3686 | N14: =IFERROR(SUMIF(P$3:P14,"CASA",L$3:L14),"") -> 50.1086 | P14: =IF(K14=0.2,"CASA","") -> CASA
B15: 46119 | C15: 1926 | D15: =IF(C15="","",C15-IF(C14<>"",C14,IF(C13<>"",C13,IF(C12<>"",C12,0)))) -> 134 | E15: 0.15 | F15: 0.8 | G15: =IF(AND(E15="",F15=""),"",IF(OR(E15>1,F15>1),(F15-E15)/100,F15-E15)) -> 0.65 | H15: =IF(G15="","",64*G15) -> 41.6 | I15: 21.393 | J15: =IFERROR(IF(OR(D15="",D15=0),"",I15/D15*100),"") -> 15.964925 | K15: 0.2 | L15: =IF(I15="","",I15*K15) -> 4.2786 | M15: =IF(B15="","",IFERROR(SUMPRODUCT(ISNUMBER(B$3:B15)*(MONTH(IF(ISNUMBER(B$3:B15),B$3:B15,1))=MONTH(B15))*(YEAR(IF(ISNUMBER(B$3:B15),B$3:B15,1))=YEAR(B15))*IF(ISNUMBER(L$3:L15),L$3:L15,0)),"")) -> 19.6472 | N15: =IFERROR(SUMIF(P$3:P15,"CASA",L$3:L15),"") -> 54.3872 | P15: =IF(K15=0.2,"CASA","") -> CASA
B16: 46122 | C16: 2075 | D16: =IF(C16="","",C16-IF(C15<>"",C15,IF(C14<>"",C14,IF(C13<>"",C13,0)))) -> 149 | E16: 0.37 | F16: 0.8 | G16: =IF(AND(E16="",F16=""),"",IF(OR(E16>1,F16>1),(F16-E16)/100,F16-E16)) -> 0.43 | H16: =IF(G16="","",64*G16) -> 27.52 | I16: 24.62 | J16: =IFERROR(IF(OR(D16="",D16=0),"",I16/D16*100),"") -> 16.52349 | K16: 0.2 | L16: =IF(I16="","",I16*K16) -> 4.924 | M16: =IF(B16="","",IFERROR(SUMPRODUCT(ISNUMBER(B$3:B16)*(MONTH(IF(ISNUMBER(B$3:B16),B$3:B16,1))=MONTH(B16))*(YEAR(IF(ISNUMBER(B$3:B16),B$3:B16,1))=YEAR(B16))*IF(ISNUMBER(L$3:L16),L$3:L16,0)),"")) -> 24.5712 | N16: =IFERROR(SUMIF(P$3:P16,"CASA",L$3:L16),"") -> 59.3112 | P16: =IF(K16=0.2,"CASA","") -> CASA
B17: 46127 | C17: 2277 | D17: =IF(C17="","",C17-IF(C16<>"",C16,IF(C15<>"",C15,IF(C14<>"",C14,0)))) -> 202 | E17: 0.19 | F17: 0.8 | G17: =IF(AND(E17="",F17=""),"",IF(OR(E17>1,F17>1),(F17-E17)/100,F17-E17)) -> 0.61 | H17: =IF(G17="","",64*G17) -> 39.04 | I17: 26.07 | J17: =IFERROR(IF(OR(D17="",D17=0),"",I17/D17*100),"") -> 12.905941 | K17: 0.2 | L17: =IF(I17="","",I17*K17) -> 5.214 | M17: =IF(B17="","",IFERROR(SUMPRODUCT(ISNUMBER(B$3:B17)*(MONTH(IF(ISNUMBER(B$3:B17),B$3:B17,1))=MONTH(B17))*(YEAR(IF(ISNUMBER(B$3:B17),B$3:B17,1))=YEAR(B17))*IF(ISNUMBER(L$3:L17),L$3:L17,0)),"")) -> 29.7852 | N17: =IFERROR(SUMIF(P$3:P17,"CASA",L$3:L17),"") -> 64.5252 | P17: =IF(K17=0.2,"CASA","") -> CASA
B18: 46130 | C18: 2414 | D18: =IF(C18="","",C18-IF(C17<>"",C17,IF(C16<>"",C16,IF(C15<>"",C15,0)))) -> 137 | E18: 0.24 | F18: 0.8 | G18: =IF(AND(E18="",F18=""),"",IF(OR(E18>1,F18>1),(F18-E18)/100,F18-E18)) -> 0.56 | H18: =IF(G18="","",64*G18) -> 35.84 | I18: 23.29 | J18: =IFERROR(IF(OR(D18="",D18=0),"",I18/D18*100),"") -> 17 | K18: 0.2 | L18: =IF(I18="","",I18*K18) -> 4.658 | M18: =IF(B18="","",IFERROR(SUMPRODUCT(ISNUMBER(B$3:B18)*(MONTH(IF(ISNUMBER(B$3:B18),B$3:B18,1))=MONTH(B18))*(YEAR(IF(ISNUMBER(B$3:B18),B$3:B18,1))=YEAR(B18))*IF(ISNUMBER(L$3:L18),L$3:L18,0)),"")) -> 34.4432 | N18: =IFERROR(SUMIF(P$3:P18,"CASA",L$3:L18),"") -> 69.1832 | P18: =IF(K18=0.2,"CASA","") -> CASA
B19: 46133 | C19: 2592 | D19: =IF(C19="","",C19-IF(C18<>"",C18,IF(C17<>"",C17,IF(C16<>"",C16,0)))) -> 178 | E19: 0.33 | F19: 0.8 | G19: =IF(AND(E19="",F19=""),"",IF(OR(E19>1,F19>1),(F19-E19)/100,F19-E19)) -> 0.47 | H19: =IF(G19="","",64*G19) -> 30.08 | I19: 26.32 | J19: =IFERROR(IF(OR(D19="",D19=0),"",I19/D19*100),"") -> 14.786517 | K19: 0.2 | L19: =IF(I19="","",I19*K19) -> 5.264 | M19: =IF(B19="","",IFERROR(SUMPRODUCT(ISNUMBER(B$3:B19)*(MONTH(IF(ISNUMBER(B$3:B19),B$3:B19,1))=MONTH(B19))*(YEAR(IF(ISNUMBER(B$3:B19),B$3:B19,1))=YEAR(B19))*IF(ISNUMBER(L$3:L19),L$3:L19,0)),"")) -> 39.7072 | N19: =IFERROR(SUMIF(P$3:P19,"CASA",L$3:L19),"") -> 74.4472 | P19: =IF(K19=0.2,"CASA","") -> CASA
B20: 46135 | C20: 2720 | D20: =IF(C20="","",C20-IF(C19<>"",C19,IF(C18<>"",C18,IF(C17<>"",C17,0)))) -> 128 | E20: 0.36 | F20: 0.78 | G20: =IF(AND(E20="",F20=""),"",IF(OR(E20>1,F20>1),(F20-E20)/100,F20-E20)) -> 0.42 | H20: =IF(G20="","",64*G20) -> 26.88 | I20: 22.72 | J20: =IFERROR(IF(OR(D20="",D20=0),"",I20/D20*100),"") -> 17.75 | K20: 0.2 | L20: =IF(I20="","",I20*K20) -> 4.544 | M20: =IF(B20="","",IFERROR(SUMPRODUCT(ISNUMBER(B$3:B20)*(MONTH(IF(ISNUMBER(B$3:B20),B$3:B20,1))=MONTH(B20))*(YEAR(IF(ISNUMBER(B$3:B20),B$3:B20,1))=YEAR(B20))*IF(ISNUMBER(L$3:L20),L$3:L20,0)),"")) -> 44.2512 | N20: =IFERROR(SUMIF(P$3:P20,"CASA",L$3:L20),"") -> 78.9912 | P20: =IF(K20=0.2,"CASA","") -> CASA
B21: 46137 | C21: 2782 | D21: =IF(C21="","",C21-IF(C20<>"",C20,IF(C19<>"",C19,IF(C18<>"",C18,0)))) -> 62 | G21: =IF(AND(E21="",F21=""),"",IF(OR(E21>1,F21>1),(F21-E21)/100,F21-E21)) | H21: =IF(G21="","",64*G21) | I21: 13.09 | J21: =IFERROR(IF(OR(D21="",D21=0),"",I21/D21*100),"") -> 21.112903 | K21: 0.2 | L21: =IF(I21="","",I21*K21) -> 2.618 | M21: =IF(B21="","",IFERROR(SUMPRODUCT(ISNUMBER(B$3:B21)*(MONTH(IF(ISNUMBER(B$3:B21),B$3:B21,1))=MONTH(B21))*(YEAR(IF(ISNUMBER(B$3:B21),B$3:B21,1))=YEAR(B21))*IF(ISNUMBER(L$3:L21),L$3:L21,0)),"")) -> 46.8692 | N21: =IFERROR(SUMIF(P$3:P21,"CASA",L$3:L21),"") -> 81.6092 | P21: =IF(K21=0.2,"CASA","") -> CASA
B22: 46140 | C22: 2909 | D22: =IF(C22="","",C22-IF(C21<>"",C21,IF(C20<>"",C20,IF(C19<>"",C19,0)))) -> 127 | E22: 0.24 | F22: 0.8 | G22: =IF(AND(E22="",F22=""),"",IF(OR(E22>1,F22>1),(F22-E22)/100,F22-E22)) -> 0.56 | H22: =IF(G22="","",64*G22) -> 35.84 | I22: 22.74 | J22: =IFERROR(IF(OR(D22="",D22=0),"",I22/D22*100),"") -> 17.905512 | K22: 0.2 | L22: =IF(I22="","",I22*K22) -> 4.548 | M22: =IF(B22="","",IFERROR(SUMPRODUCT(ISNUMBER(B$3:B22)*(MONTH(IF(ISNUMBER(B$3:B22),B$3:B22,1))=MONTH(B22))*(YEAR(IF(ISNUMBER(B$3:B22),B$3:B22,1))=YEAR(B22))*IF(ISNUMBER(L$3:L22),L$3:L22,0)),"")) -> 51.4172 | N22: =IFERROR(SUMIF(P$3:P22,"CASA",L$3:L22),"") -> 86.1572 | P22: =IF(K22=0.2,"CASA","") -> CASA
A23: =IF(ISNUMBER(B24),CHOOSE(MONTH(B24),"GENNAIO","FEBBRAIO","MARZO","APRILE","MAGGIO","GIUGNO","LUGLIO","AGOSTO","SETTEMBRE","OTTOBRE","NOVEMBRE","DICEMBRE")&" "&YEAR(B24),"") -> MAGGIO 2026 | D23: =IF(C23="","",C23-IF(C22<>"",C22,IF(C21<>"",C21,IF(C20<>"",C20,0)))) | O23: =IF(ISNUMBER(B24),CHOOSE(MONTH(B24),"GENNAIO","FEBBRAIO","MARZO","APRILE","MAGGIO","GIUGNO","LUGLIO","AGOSTO","SETTEMBRE","OTTOBRE","NOVEMBRE","DICEMBRE")&" "&YEAR(B24),"") -> MAGGIO 2026
B24: 46143 | C24: 3042 | D24: =IF(C24="","",C24-IF(C23<>"",C23,IF(C22<>"",C22,IF(C21<>"",C21,0)))) -> 133 | E24: 0.45 | F24: 0.8 | G24: =IF(AND(E24="",F24=""),"",IF(OR(E24>1,F24>1),(F24-E24)/100,F24-E24)) -> 0.35 | H24: =IF(G24="","",64*G24) -> 22.4 | I24: 23.36 | J24: =IFERROR(IF(OR(D24="",D24=0),"",I24/D24*100),"") -> 17.56391 | K24: 0.2 | L24: =IF(I24="","",I24*K24) -> 4.672 | M24: =IF(B24="","",IFERROR(SUMPRODUCT(ISNUMBER(B$3:B24)*(MONTH(IF(ISNUMBER(B$3:B24),B$3:B24,1))=MONTH(B24))*(YEAR(IF(ISNUMBER(B$3:B24),B$3:B24,1))=YEAR(B24))*IF(ISNUMBER(L$3:L24),L$3:L24,0)),"")) -> 4.672 | N24: =IFERROR(SUMIF(P$3:P24,"CASA",L$3:L24),"") -> 90.8292 | P24: =IF(K24=0.2,"CASA","") -> CASA
A25: =IF(ISNUMBER(B26),CHOOSE(MONTH(B26),"GENNAIO","FEBBRAIO","MARZO","APRILE","MAGGIO","GIUGNO","LUGLIO","AGOSTO","SETTEMBRE","OTTOBRE","NOVEMBRE","DICEMBRE")&" "&YEAR(B26),"") -> AGOSTO 2026 | D25: =IF(C25="","",C25-IF(C24<>"",C24,IF(C23<>"",C23,IF(C22<>"",C22,0)))) | O25: =IF(ISNUMBER(B26),CHOOSE(MONTH(B26),"GENNAIO","FEBBRAIO","MARZO","APRILE","MAGGIO","GIUGNO","LUGLIO","AGOSTO","SETTEMBRE","OTTOBRE","NOVEMBRE","DICEMBRE")&" "&YEAR(B26),"") -> AGOSTO 2026
B26: 46235 | C26: 3100 | D26: =IF(C26="","",C26-IF(C25<>"",C25,IF(C24<>"",C24,IF(C23<>"",C23,0)))) -> 58 | E26: 0.3 | F26: 0.8 | G26: =IF(AND(E26="",F26=""),"",IF(OR(E26>1,F26>1),(F26-E26)/100,F26-E26)) -> 0.5 | H26: =IF(G26="","",64*G26) -> 32 | I26: 32 | J26: =IFERROR(IF(OR(D26="",D26=0),"",I26/D26*100),"") -> 55.172414 | K26: 0.2 | L26: =IF(I26="","",I26*K26) -> 6.4 | M26: =IF(B26="","",IFERROR(SUMPRODUCT(ISNUMBER(B$3:B26)*(MONTH(IF(ISNUMBER(B$3:B26),B$3:B26,1))=MONTH(B26))*(YEAR(IF(ISNUMBER(B$3:B26),B$3:B26,1))=YEAR(B26))*IF(ISNUMBER(L$3:L26),L$3:L26,0)),"")) -> 6.4 | N26: =IFERROR(SUMIF(P$3:P26,"CASA",L$3:L26),"") -> 97.2292 | P26: =IF(K26=0.2,"CASA","") -> CASA
A27: =IF(AND(B27="",ISNUMBER(B28)),CHOOSE(MONTH(B28),"GENNAIO","FEBBRAIO","MARZO","APRILE","MAGGIO","GIUGNO","LUGLIO","AGOSTO","SETTEMBRE","OTTOBRE","NOVEMBRE","DICEMBRE")&" "&YEAR(B28),"") | D27: =IF(C27="","",C27-IF(C26<>"",C26,IF(C25<>"",C25,IF(C24<>"",C24,0)))) | G27: =IF(AND(E27="",F27=""),"",IF(OR(E27>1,F27>1),(F27-E27)/100,F27-E27)) | H27: =IF(G27="","",64*G27) | J27: =IFERROR(IF(OR(D27="",D27=0),"",I27/D27*100),"") | L27: =IF(I27="","",I27*K27) | M27: =IF(B27="","",IFERROR(SUMPRODUCT(ISNUMBER(B$3:B27)*(MONTH(IF(ISNUMBER(B$3:B27),B$3:B27,1))=MONTH(B27))*(YEAR(IF(ISNUMBER(B$3:B27),B$3:B27,1))=YEAR(B27))*IF(ISNUMBER(L$3:L27),L$3:L27,0)),"")) | O27: =IF(AND(B27="",ISNUMBER(B28)),CHOOSE(MONTH(B28),"GENNAIO","FEBBRAIO","MARZO","APRILE","MAGGIO","GIUGNO","LUGLIO","AGOSTO","SETTEMBRE","OTTOBRE","NOVEMBRE","DICEMBRE")&" "&YEAR(B28),"") | P27: =IF(K27=0.2,"CASA","")
A28: =IF(AND(B28="",ISNUMBER(B29)),CHOOSE(MONTH(B29),"GENNAIO","FEBBRAIO","MARZO","APRILE","MAGGIO","GIUGNO","LUGLIO","AGOSTO","SETTEMBRE","OTTOBRE","NOVEMBRE","DICEMBRE")&" "&YEAR(B29),"") | D28: =IF(C28="","",C28-IF(C27<>"",C27,IF(C26<>"",C26,IF(C25<>"",C25,0)))) | G28: =IF(AND(E28="",F28=""),"",IF(OR(E28>1,F28>1),(F28-E28)/100,F28-E28)) | H28: =IF(G28="","",64*G28) | J28: =IFERROR(IF(OR(D28="",D28=0),"",I28/D28*100),"") | L28: =IF(I28="","",I28*K28) | M28: =IF(B28="","",IFERROR(SUMPRODUCT(ISNUMBER(B$3:B28)*(MONTH(IF(ISNUMBER(B$3:B28),B$3:B28,1))=MONTH(B28))*(YEAR(IF(ISNUMBER(B$3:B28),B$3:B28,1))=YEAR(B28))*IF(ISNUMBER(L$3:L28),L$3:L28,0)),"")) | O28: =IF(AND(B28="",ISNUMBER(B29)),CHOOSE(MONTH(B29),"GENNAIO","FEBBRAIO","MARZO","APRILE","MAGGIO","GIUGNO","LUGLIO","AGOSTO","SETTEMBRE","OTTOBRE","NOVEMBRE","DICEMBRE")&" "&YEAR(B29),"") | P28: =IF(K28=0.2,"CASA","")
A29: =IF(AND(B29="",ISNUMBER(B30)),CHOOSE(MONTH(B30),"GENNAIO","FEBBRAIO","MARZO","APRILE","MAGGIO","GIUGNO","LUGLIO","AGOSTO","SETTEMBRE","OTTOBRE","NOVEMBRE","DICEMBRE")&" "&YEAR(B30),"") | C29: 3300 | D29: =IF(C29="","",C29-IF(C28<>"",C28,IF(C27<>"",C27,IF(C26<>"",C26,0)))) -> 200 | G29: =IF(AND(E29="",F29=""),"",IF(OR(E29>1,F29>1),(F29-E29)/100,F29-E29)) | H29: =IF(G29="","",64*G29) | J29: =IFERROR(IF(OR(D29="",D29=0),"",I29/D29*100),"") -> 0 | L29: =IF(I29="","",I29*K29) | M29: =IF(B29="","",IFERROR(SUMPRODUCT(ISNUMBER(B$3:B29)*(MONTH(IF(ISNUMBER(B$3:B29),B$3:B29,1))=MONTH(B29))*(YEAR(IF(ISNUMBER(B$3:B29),B$3:B29,1))=YEAR(B29))*IF(ISNUMBER(L$3:L29),L$3:L29,0)),"")) | O29: =IF(AND(B29="",ISNUMBER(B30)),CHOOSE(MONTH(B30),"GENNAIO","FEBBRAIO","MARZO","APRILE","MAGGIO","GIUGNO","LUGLIO","AGOSTO","SETTEMBRE","OTTOBRE","NOVEMBRE","DICEMBRE")&" "&YEAR(B30),"") | P29: =IF(K29=0.2,"CASA","")
A30: =IF(AND(B30="",ISNUMBER(B31)),CHOOSE(MONTH(B31),"GENNAIO","FEBBRAIO","MARZO","APRILE","MAGGIO","GIUGNO","LUGLIO","AGOSTO","SETTEMBRE","OTTOBRE","NOVEMBRE","DICEMBRE")&" "&YEAR(B31),"") | D30: =IF(C30="","",C30-IF(C29<>"",C29,IF(C28<>"",C28,IF(C27<>"",C27,0)))) | G30: =IF(AND(E30="",F30=""),"",IF(OR(E30>1,F30>1),(F30-E30)/100,F30-E30)) | H30: =IF(G30="","",64*G30) | J30: =IFERROR(IF(OR(D30="",D30=0),"",I30/D30*100),"") | L30: =IF(I30="","",I30*K30) | M30: =IF(B30="","",IFERROR(SUMPRODUCT(ISNUMBER(B$3:B30)*(MONTH(IF(ISNUMBER(B$3:B30),B$3:B30,1))=MONTH(B30))*(YEAR(IF(ISNUMBER(B$3:B30),B$3:B30,1))=YEAR(B30))*IF(ISNUMBER(L$3:L30),L$3:L30,0)),"")) | O30: =IF(AND(B30="",ISNUMBER(B31)),CHOOSE(MONTH(B31),"GENNAIO","FEBBRAIO","MARZO","APRILE","MAGGIO","GIUGNO","LUGLIO","AGOSTO","SETTEMBRE","OTTOBRE","NOVEMBRE","DICEMBRE")&" "&YEAR(B31),"") | P30: =IF(K30=0.2,"CASA","")
A31: =IF(AND(B31="",ISNUMBER(B32)),CHOOSE(MONTH(B32),"GENNAIO","FEBBRAIO","MARZO","APRILE","MAGGIO","GIUGNO","LUGLIO","AGOSTO","SETTEMBRE","OTTOBRE","NOVEMBRE","DICEMBRE")&" "&YEAR(B32),"") | D31: =IF(C31="","",C31-IF(C30<>"",C30,IF(C29<>"",C29,IF(C28<>"",C28,0)))) | G31: =IF(AND(E31="",F31=""),"",IF(OR(E31>1,F31>1),(F31-E31)/100,F31-E31)) | H31: =IF(G31="","",64*G31) | J31: =IFERROR(IF(OR(D31="",D31=0),"",I31/D31*100),"") | L31: =IF(I31="","",I31*K31) | M31: =IF(B31="","",IFERROR(SUMPRODUCT(ISNUMBER(B$3:B31)*(MONTH(IF(ISNUMBER(B$3:B31),B$3:B31,1))=MONTH(B31))*(YEAR(IF(ISNUMBER(B$3:B31),B$3:B31,1))=YEAR(B31))*IF(ISNUMBER(L$3:L31),L$3:L31,0)),"")) | O31: =IF(AND(B31="",ISNUMBER(B32)),CHOOSE(MONTH(B32),"GENNAIO","FEBBRAIO","MARZO","APRILE","MAGGIO","GIUGNO","LUGLIO","AGOSTO","SETTEMBRE","OTTOBRE","NOVEMBRE","DICEMBRE")&" "&YEAR(B32),"") | P31: =IF(K31=0.2,"CASA","")
A32: =IF(AND(B32="",ISNUMBER(B33)),CHOOSE(MONTH(B33),"GENNAIO","FEBBRAIO","MARZO","APRILE","MAGGIO","GIUGNO","LUGLIO","AGOSTO","SETTEMBRE","OTTOBRE","NOVEMBRE","DICEMBRE")&" "&YEAR(B33),"") | C32: 3300 | D32: =IF(C32="","",C32-IF(C31<>"",C31,IF(C30<>"",C30,IF(C29<>"",C29,0)))) -> 0 | G32: =IF(AND(E32="",F32=""),"",IF(OR(E32>1,F32>1),(F32-E32)/100,F32-E32)) | H32: =IF(G32="","",64*G32) | J32: =IFERROR(IF(OR(D32="",D32=0),"",I32/D32*100),"") | L32: =IF(I32="","",I32*K32) | M32: =IF(B32="","",IFERROR(SUMPRODUCT(ISNUMBER(B$3:B32)*(MONTH(IF(ISNUMBER(B$3:B32),B$3:B32,1))=MONTH(B32))*(YEAR(IF(ISNUMBER(B$3:B32),B$3:B32,1))=YEAR(B32))*IF(ISNUMBER(L$3:L32),L$3:L32,0)),"")) | O32: =IF(AND(B32="",ISNUMBER(B33)),CHOOSE(MONTH(B33),"GENNAIO","FEBBRAIO","MARZO","APRILE","MAGGIO","GIUGNO","LUGLIO","AGOSTO","SETTEMBRE","OTTOBRE","NOVEMBRE","DICEMBRE")&" "&YEAR(B33),"") | P32: =IF(K32=0.2,"CASA","")
A33: =IF(AND(B33="",ISNUMBER(B34)),CHOOSE(MONTH(B34),"GENNAIO","FEBBRAIO","MARZO","APRILE","MAGGIO","GIUGNO","LUGLIO","AGOSTO","SETTEMBRE","OTTOBRE","NOVEMBRE","DICEMBRE")&" "&YEAR(B34),"") -> DICEMBRE 2026 | D33: =IF(C33="","",C33-IF(C32<>"",C32,IF(C31<>"",C31,IF(C30<>"",C30,0)))) | G33: =IF(AND(E33="",F33=""),"",IF(OR(E33>1,F33>1),(F33-E33)/100,F33-E33)) | H33: =IF(G33="","",64*G33) | J33: =IFERROR(IF(OR(D33="",D33=0),"",I33/D33*100),"") | L33: =IF(I33="","",I33*K33) | M33: =IF(B33="","",IFERROR(SUMPRODUCT(ISNUMBER(B$3:B33)*(MONTH(IF(ISNUMBER(B$3:B33),B$3:B33,1))=MONTH(B33))*(YEAR(IF(ISNUMBER(B$3:B33),B$3:B33,1))=YEAR(B33))*IF(ISNUMBER(L$3:L33),L$3:L33,0)),"")) | O33: =IF(AND(B33="",ISNUMBER(B34)),CHOOSE(MONTH(B34),"GENNAIO","FEBBRAIO","MARZO","APRILE","MAGGIO","GIUGNO","LUGLIO","AGOSTO","SETTEMBRE","OTTOBRE","NOVEMBRE","DICEMBRE")&" "&YEAR(B34),"") -> DICEMBRE 2026 | P33: =IF(K33=0.2,"CASA","")
A34: =IF(AND(B34="",ISNUMBER(B35)),CHOOSE(MONTH(B35),"GENNAIO","FEBBRAIO","MARZO","APRILE","MAGGIO","GIUGNO","LUGLIO","AGOSTO","SETTEMBRE","OTTOBRE","NOVEMBRE","DICEMBRE")&" "&YEAR(B35),"") | B34: 46366 | C34: 3300 | D34: =IF(C34="","",C34-IF(C33<>"",C33,IF(C32<>"",C32,IF(C31<>"",C31,0)))) -> 0 | E34: 20 | F34: 40 | G34: =IF(AND(E34="",F34=""),"",IF(OR(E34>1,F34>1),(F34-E34)/100,F34-E34)) -> 0.2 | H34: =IF(G34="","",64*G34) -> 12.8 | I34: 12 | J34: =IFERROR(IF(OR(D34="",D34=0),"",I34/D34*100),"") | K34: 0.2 | L34: =IF(I34="","",I34*K34) -> 2.4 | M34: =IF(B34="","",IFERROR(SUMPRODUCT(ISNUMBER(B$3:B34)*(MONTH(IF(ISNUMBER(B$3:B34),B$3:B34,1))=MONTH(B34))*(YEAR(IF(ISNUMBER(B$3:B34),B$3:B34,1))=YEAR(B34))*IF(ISNUMBER(L$3:L34),L$3:L34,0)),"")) | N34: =IFERROR(SUMIF(P$3:P34,"CASA",L$3:L34),"") -> 99.6292 | O34: =IF(AND(B34="",ISNUMBER(B35)),CHOOSE(MONTH(B35),"GENNAIO","FEBBRAIO","MARZO","APRILE","MAGGIO","GIUGNO","LUGLIO","AGOSTO","SETTEMBRE","OTTOBRE","NOVEMBRE","DICEMBRE")&" "&YEAR(B35),"") | P34: =IF(K34=0.2,"CASA","") -> CASA
A35: =IF(AND(B35="",ISNUMBER(B36)),CHOOSE(MONTH(B36),"GENNAIO","FEBBRAIO","MARZO","APRILE","MAGGIO","GIUGNO","LUGLIO","AGOSTO","SETTEMBRE","OTTOBRE","NOVEMBRE","DICEMBRE")&" "&YEAR(B36),"") | D35: =IF(C35="","",C35-IF(C34<>"",C34,IF(C33<>"",C33,IF(C32<>"",C32,0)))) | G35: =IF(AND(E35="",F35=""),"",IF(OR(E35>1,F35>1),(F35-E35)/100,F35-E35)) | H35: =IF(G35="","",64*G35) | J35: =IFERROR(IF(OR(D35="",D35=0),"",I35/D35*100),"") | L35: =IF(I35="","",I35*K35) | M35: =IF(B35="","",IFERROR(SUMPRODUCT(ISNUMBER(B$3:B35)*(MONTH(IF(ISNUMBER(B$3:B35),B$3:B35,1))=MONTH(B35))*(YEAR(IF(ISNUMBER(B$3:B35),B$3:B35,1))=YEAR(B35))*IF(ISNUMBER(L$3:L35),L$3:L35,0)),"")) | O35: =IF(AND(B35="",ISNUMBER(B36)),CHOOSE(MONTH(B36),"GENNAIO","FEBBRAIO","MARZO","APRILE","MAGGIO","GIUGNO","LUGLIO","AGOSTO","SETTEMBRE","OTTOBRE","NOVEMBRE","DICEMBRE")&" "&YEAR(B36),"") | P35: =IF(K35=0.2,"CASA","")
A36: =IF(AND(B36="",ISNUMBER(B37)),CHOOSE(MONTH(B37),"GENNAIO","FEBBRAIO","MARZO","APRILE","MAGGIO","GIUGNO","LUGLIO","AGOSTO","SETTEMBRE","OTTOBRE","NOVEMBRE","DICEMBRE")&" "&YEAR(B37),"") -> AGOSTO 2026 | D36: =IF(C36="","",C36-IF(C35<>"",C35,IF(C34<>"",C34,IF(C33<>"",C33,0)))) | G36: =IF(AND(E36="",F36=""),"",IF(OR(E36>1,F36>1),(F36-E36)/100,F36-E36)) | H36: =IF(G36="","",64*G36) | J36: =IFERROR(IF(OR(D36="",D36=0),"",I36/D36*100),"") | L36: =IF(I36="","",I36*K36) | M36: =IF(B36="","",IFERROR(SUMPRODUCT(ISNUMBER(B$3:B36)*(MONTH(IF(ISNUMBER(B$3:B36),B$3:B36,1))=MONTH(B36))*(YEAR(IF(ISNUMBER(B$3:B36),B$3:B36,1))=YEAR(B36))*IF(ISNUMBER(L$3:L36),L$3:L36,0)),"")) | O36: =IF(AND(B36="",ISNUMBER(B37)),CHOOSE(MONTH(B37),"GENNAIO","FEBBRAIO","MARZO","APRILE","MAGGIO","GIUGNO","LUGLIO","AGOSTO","SETTEMBRE","OTTOBRE","NOVEMBRE","DICEMBRE")&" "&YEAR(B37),"") -> AGOSTO 2026 | P36: =IF(K36=0.2,"CASA","")
A37: =IF(AND(B37="",ISNUMBER(B38)),CHOOSE(MONTH(B38),"GENNAIO","FEBBRAIO","MARZO","APRILE","MAGGIO","GIUGNO","LUGLIO","AGOSTO","SETTEMBRE","OTTOBRE","NOVEMBRE","DICEMBRE")&" "&YEAR(B38),"") | B37: 46246 | C37: 4000 | D37: =IF(C37="","",C37-IF(C36<>"",C36,IF(C35<>"",C35,IF(C34<>"",C34,0)))) -> 700 | E37: 20 | F37: 40 | G37: =IF(AND(E37="",F37=""),"",IF(OR(E37>1,F37>1),(F37-E37)/100,F37-E37)) -> 0.2 | H37: =IF(G37="","",64*G37) -> 12.8 | I37: 12 | J37: =IFERROR(IF(OR(D37="",D37=0),"",I37/D37*100),"") -> 1.7142857 | K37: 0.2 | L37: =IF(I37="","",I37*K37) -> 2.4 | M37: =IF(B37="","",IFERROR(SUMPRODUCT(ISNUMBER(B$3:B37)*(MONTH(IF(ISNUMBER(B$3:B37),B$3:B37,1))=MONTH(B37))*(YEAR(IF(ISNUMBER(B$3:B37),B$3:B37,1))=YEAR(B37))*IF(ISNUMBER(L$3:L37),L$3:L37,0)),"")) | O37: =IF(AND(B37="",ISNUMBER(B38)),CHOOSE(MONTH(B38),"GENNAIO","FEBBRAIO","MARZO","APRILE","MAGGIO","GIUGNO","LUGLIO","AGOSTO","SETTEMBRE","OTTOBRE","NOVEMBRE","DICEMBRE")&" "&YEAR(B38),"") | P37: =IF(K37=0.2,"CASA","") -> CASA
A38: =IF(AND(B38="",ISNUMBER(B39)),CHOOSE(MONTH(B39),"GENNAIO","FEBBRAIO","MARZO","APRILE","MAGGIO","GIUGNO","LUGLIO","AGOSTO","SETTEMBRE","OTTOBRE","NOVEMBRE","DICEMBRE")&" "&YEAR(B39),"") | D38: =IF(C38="","",C38-IF(C37<>"",C37,IF(C36<>"",C36,IF(C35<>"",C35,0)))) | G38: =IF(AND(E38="",F38=""),"",IF(OR(E38>1,F38>1),(F38-E38)/100,F38-E38)) | H38: =IF(G38="","",64*G38) | J38: =IFERROR(IF(OR(D38="",D38=0),"",I38/D38*100),"") | L38: =IF(I38="","",I38*K38) | M38: =IF(B38="","",IFERROR(SUMPRODUCT(ISNUMBER(B$3:B38)*(MONTH(IF(ISNUMBER(B$3:B38),B$3:B38,1))=MONTH(B38))*(YEAR(IF(ISNUMBER(B$3:B38),B$3:B38,1))=YEAR(B38))*IF(ISNUMBER(L$3:L38),L$3:L38,0)),"")) | O38: =IF(AND(B38="",ISNUMBER(B39)),CHOOSE(MONTH(B39),"GENNAIO","FEBBRAIO","MARZO","APRILE","MAGGIO","GIUGNO","LUGLIO","AGOSTO","SETTEMBRE","OTTOBRE","NOVEMBRE","DICEMBRE")&" "&YEAR(B39),"") | P38: =IF(K38=0.2,"CASA","")
A39: =IF(AND(B39="",ISNUMBER(B40)),CHOOSE(MONTH(B40),"GENNAIO","FEBBRAIO","MARZO","APRILE","MAGGIO","GIUGNO","LUGLIO","AGOSTO","SETTEMBRE","OTTOBRE","NOVEMBRE","DICEMBRE")&" "&YEAR(B40),"") | D39: =IF(C39="","",C39-IF(C38<>"",C38,IF(C37<>"",C37,IF(C36<>"",C36,0)))) | G39: =IF(AND(E39="",F39=""),"",IF(OR(E39>1,F39>1),(F39-E39)/100,F39-E39)) | H39: =IF(G39="","",64*G39) | J39: =IFERROR(IF(OR(D39="",D39=0),"",I39/D39*100),"") | L39: =IF(I39="","",I39*K39) | M39: =IF(B39="","",IFERROR(SUMPRODUCT(ISNUMBER(B$3:B39)*(MONTH(IF(ISNUMBER(B$3:B39),B$3:B39,1))=MONTH(B39))*(YEAR(IF(ISNUMBER(B$3:B39),B$3:B39,1))=YEAR(B39))*IF(ISNUMBER(L$3:L39),L$3:L39,0)),"")) | O39: =IF(AND(B39="",ISNUMBER(B40)),CHOOSE(MONTH(B40),"GENNAIO","FEBBRAIO","MARZO","APRILE","MAGGIO","GIUGNO","LUGLIO","AGOSTO","SETTEMBRE","OTTOBRE","NOVEMBRE","DICEMBRE")&" "&YEAR(B40),"") | P39: =IF(K39=0.2,"CASA","")
A40: =IF(AND(B40="",ISNUMBER(B41)),CHOOSE(MONTH(B41),"GENNAIO","FEBBRAIO","MARZO","APRILE","MAGGIO","GIUGNO","LUGLIO","AGOSTO","SETTEMBRE","OTTOBRE","NOVEMBRE","DICEMBRE")&" "&YEAR(B41),"") | D40: =IF(C40="","",C40-IF(C39<>"",C39,IF(C38<>"",C38,IF(C37<>"",C37,0)))) | G40: =IF(AND(E40="",F40=""),"",IF(OR(E40>1,F40>1),(F40-E40)/100,F40-E40)) | H40: =IF(G40="","",64*G40) | J40: =IFERROR(IF(OR(D40="",D40=0),"",I40/D40*100),"") | L40: =IF(I40="","",I40*K40) | M40: =IF(B40="","",IFERROR(SUMPRODUCT(ISNUMBER(B$3:B40)*(MONTH(IF(ISNUMBER(B$3:B40),B$3:B40,1))=MONTH(B40))*(YEAR(IF(ISNUMBER(B$3:B40),B$3:B40,1))=YEAR(B40))*IF(ISNUMBER(L$3:L40),L$3:L40,0)),"")) | O40: =IF(AND(B40="",ISNUMBER(B41)),CHOOSE(MONTH(B41),"GENNAIO","FEBBRAIO","MARZO","APRILE","MAGGIO","GIUGNO","LUGLIO","AGOSTO","SETTEMBRE","OTTOBRE","NOVEMBRE","DICEMBRE")&" "&YEAR(B41),"") | P40: =IF(K40=0.2,"CASA","")
...

Sheet Formule v1.1
A1: DATA | B1: KM TOTALI | C1: KM PARZIALI | D1: % PRIMA DELLA CARICA | E1: % DOPO LA CARICA | F1: % CARICATA | G1: KWh | H1: KWh EFFETTIVI | I1: KWh/ 100 KM | J1: PREZZO/ KWh | K1: COSTO | L1: COSTO MENSILE | M1: PROGRESSIVO CASA | N1: DOVE
A2: =IF(Dati!A2="","",Dati!A2) -> 46080 | B2: =IF(Dati!B2="","",Dati!B2) -> 286 | C2: =IF(B2="","",B2) -> 286 | D2: =IF(Dati!C2="","",IF(Dati!C2>1,Dati!C2/100,Dati!C2)) -> 0.26 | E2: =IF(Dati!D2="","",IF(Dati!D2>1,Dati!D2/100,Dati!D2)) -> 0.86 | F2: =IF(OR(D2="",E2=""),"",IF(OR(D2>1,E2>1),(E2-D2)/100,E2-D2)) -> 0.6 | G2: =IF(F2="","",IF(64*F2=0,"",64*F2)) -> 38.4 | H2: =IF(Dati!E2="","",Dati!E2) -> 39.34 | I2: =IFERROR(IF(OR(C2="",C2=0),"",H2/C2*100),"") -> 13.755245 | J2: =IF(Dati!F2="","",Dati!F2) -> 0.5 | K2: =IF(OR(H2="",J2=""),"",IF(H2*J2=0,"",H2*J2)) -> 19.67 | L2: =IF(A2="","",IFERROR(IF(SUMPRODUCT((ISNUMBER(A$2:A2))*(A$2:A2>1000)*(MONTH(IF(ISNUMBER(A$2:A2),A$2:A2,1))=MONTH(A2))*(YEAR(IF(ISNUMBER(A$2:A2),A$2:A2,1))=YEAR(A2))*IF(ISNUMBER(K$2:K2),K$2:K2,0))=0,"",SUMPRODUCT((ISNUMBER(A$2:A2))*(A$2:A2>1000)*(MONTH(IF(ISNUMBER(A$2:A2),A$2:A2,1))=MONTH(A2))*(YEAR(IF(ISNUMBER(A$2:A2),A$2:A2,1))=YEAR(A2))*IF(ISNUMBER(K$2:K2),K$2:K2,0))),"")) -> 19.67 | M2: =IF(A2="","",IFERROR(IF(SUMIF(N$2:N2,"CASA",K$2:K2)=0,"",SUMIF(N$2:N2,"CASA",K$2:K2)),"")) | N2: =IF(J2="","",IF(J2=0.2,"CASA",IF(Dati!G2="","",Dati!G2))) -> EVDC
A3: =IF(Dati!A3="","",Dati!A3) -> 46085 | B3: =IF(Dati!B3="","",Dati!B3) -> 533 | C3: =IF(B3="","",IF(ISNUMBER(B2),IF(B3-B2<0,B3,IF(B3-B2=0,"",B3-B2)),B3)) -> 247 | D3: =IF(Dati!C3="","",IF(Dati!C3>1,Dati!C3/100,Dati!C3)) -> 0.14 | E3: =IF(Dati!D3="","",IF(Dati!D3>1,Dati!D3/100,Dati!D3)) -> 0.86 | F3: =IF(OR(D3="",E3=""),"",IF(OR(D3>1,E3>1),(E3-D3)/100,E3-D3)) -> 0.72 | G3: =IF(F3="","",IF(64*F3=0,"",64*F3)) -> 46.08 | H3: =IF(Dati!E3="","",Dati!E3) -> 46.156 | I3: =IFERROR(IF(OR(C3="",C3=0),"",H3/C3*100),"") -> 18.68664 | J3: =IF(Dati!F3="","",Dati!F3) -> 0.5 | K3: =IF(OR(H3="",J3=""),"",IF(H3*J3=0,"",H3*J3)) -> 23.078 | L3: =IF(A3="","",IFERROR(IF(SUMPRODUCT((ISNUMBER(A$2:A3))*(A$2:A3>1000)*(MONTH(IF(ISNUMBER(A$2:A3),A$2:A3,1))=MONTH(A3))*(YEAR(IF(ISNUMBER(A$2:A3),A$2:A3,1))=YEAR(A3))*IF(ISNUMBER(K$2:K3),K$2:K3,0))=0,"",SUMPRODUCT((ISNUMBER(A$2:A3))*(A$2:A3>1000)*(MONTH(IF(ISNUMBER(A$2:A3),A$2:A3,1))=MONTH(A3))*(YEAR(IF(ISNUMBER(A$2:A3),A$2:A3,1))=YEAR(A3))*IF(ISNUMBER(K$2:K3),K$2:K3,0))),"")) -> 23.078 | M3: =IF(A3="","",IFERROR(IF(SUMIF(N$2:N3,"CASA",K$2:K3)=0,"",SUMIF(N$2:N3,"CASA",K$2:K3)),"")) | N3: =IF(J3="","",IF(J3=0.2,"CASA",IF(Dati!G3="","",Dati!G3))) -> EVDC
A4: =IF(Dati!A4="","",Dati!A4) -> 46092 | B4: =IF(Dati!B4="","",Dati!B4) -> 758 | C4: =IF(B4="","",IF(ISNUMBER(B3),IF(B4-B3<0,B4,IF(B4-B3=0,"",B4-B3)),B4)) -> 225 | D4: =IF(Dati!C4="","",IF(Dati!C4>1,Dati!C4/100,Dati!C4)) -> 0.18 | E4: =IF(Dati!D4="","",IF(Dati!D4>1,Dati!D4/100,Dati!D4)) -> 0.8 | F4: =IF(OR(D4="",E4=""),"",IF(OR(D4>1,E4>1),(E4-D4)/100,E4-D4)) -> 0.62 | G4: =IF(F4="","",IF(64*F4=0,"",64*F4)) -> 39.68 | H4: =IF(Dati!E4="","",Dati!E4) -> 40.374 | I4: =IFERROR(IF(OR(C4="",C4=0),"",H4/C4*100),"") -> 17.944 | J4: =IF(Dati!F4="","",Dati!F4) -> 0.649 | K4: =IF(OR(H4="",J4=""),"",IF(H4*J4=0,"",H4*J4)) -> 26.202726 | L4: =IF(A4="","",IFERROR(IF(SUMPRODUCT((ISNUMBER(A$2:A4))*(A$2:A4>1000)*(MONTH(IF(ISNUMBER(A$2:A4),A$2:A4,1))=MONTH(A4))*(YEAR(IF(ISNUMBER(A$2:A4),A$2:A4,1))=YEAR(A4))*IF(ISNUMBER(K$2:K4),K$2:K4,0))=0,"",SUMPRODUCT((ISNUMBER(A$2:A4))*(A$2:A4>1000)*(MONTH(IF(ISNUMBER(A$2:A4),A$2:A4,1))=MONTH(A4))*(YEAR(IF(ISNUMBER(A$2:A4),A$2:A4,1))=YEAR(A4))*IF(ISNUMBER(K$2:K4),K$2:K4,0))),"")) -> 49.280726 | M4: =IF(A4="","",IFERROR(IF(SUMIF(N$2:N4,"CASA",K$2:K4)=0,"",SUMIF(N$2:N4,"CASA",K$2:K4)),"")) | N4: =IF(J4="","",IF(J4=0.2,"CASA",IF(Dati!G4="","",Dati!G4))) -> next charge
A5: =IF(Dati!A5="","",Dati!A5) -> 46096 | B5: =IF(Dati!B5="","",Dati!B5) -> 926 | C5: =IF(B5="","",IF(ISNUMBER(B4),IF(B5-B4<0,B5,IF(B5-B4=0,"",B5-B4)),B5)) -> 168 | D5: =IF(Dati!C5="","",IF(Dati!C5>1,Dati!C5/100,Dati!C5)) -> 0.37 | E5: =IF(Dati!D5="","",IF(Dati!D5>1,Dati!D5/100,Dati!D5)) -> 0.85 | F5: =IF(OR(D5="",E5=""),"",IF(OR(D5>1,E5>1),(E5-D5)/100,E5-D5)) -> 0.48 | G5: =IF(F5="","",IF(64*F5=0,"",64*F5)) -> 30.72 | H5: =IF(Dati!E5="","",Dati!E5) -> 30.8 | I5: =IFERROR(IF(OR(C5="",C5=0),"",H5/C5*100),"") -> 18.333333 | J5: =IF(Dati!F5="","",Dati!F5) -> 0.5 | K5: =IF(OR(H5="",J5=""),"",IF(H5*J5=0,"",H5*J5)) -> 15.4 | L5: =IF(A5="","",IFERROR(IF(SUMPRODUCT((ISNUMBER(A$2:A5))*(A$2:A5>1000)*(MONTH(IF(ISNUMBER(A$2:A5),A$2:A5,1))=MONTH(A5))*(YEAR(IF(ISNUMBER(A$2:A5),A$2:A5,1))=YEAR(A5))*IF(ISNUMBER(K$2:K5),K$2:K5,0))=0,"",SUMPRODUCT((ISNUMBER(A$2:A5))*(A$2:A5>1000)*(MONTH(IF(ISNUMBER(A$2:A5),A$2:A5,1))=MONTH(A5))*(YEAR(IF(ISNUMBER(A$2:A5),A$2:A5,1))=YEAR(A5))*IF(ISNUMBER(K$2:K5),K$2:K5,0))),"")) -> 64.680726 | M5: =IF(A5="","",IFERROR(IF(SUMIF(N$2:N5,"CASA",K$2:K5)=0,"",SUMIF(N$2:N5,"CASA",K$2:K5)),"")) | N5: =IF(J5="","",IF(J5=0.2,"CASA",IF(Dati!G5="","",Dati!G5))) -> EVDC
A6: =IF(Dati!A6="","",Dati!A6) -> 46101 | B6: =IF(Dati!B6="","",Dati!B6) -> 1130 | C6: =IF(B6="","",IF(ISNUMBER(B5),IF(B6-B5<0,B6,IF(B6-B5=0,"",B6-B5)),B6)) -> 204 | D6: =IF(Dati!C6="","",IF(Dati!C6>1,Dati!C6/100,Dati!C6)) -> 0.3 | E6: =IF(Dati!D6="","",IF(Dati!D6>1,Dati!D6/100,Dati!D6)) -> 0.84 | F6: =IF(OR(D6="",E6=""),"",IF(OR(D6>1,E6>1),(E6-D6)/100,E6-D6)) -> 0.54 | G6: =IF(F6="","",IF(64*F6=0,"",64*F6)) -> 34.56 | H6: =IF(Dati!E6="","",Dati!E6) -> 34.08 | I6: =IFERROR(IF(OR(C6="",C6=0),"",H6/C6*100),"") -> 16.705882 | J6: =IF(Dati!F6="","",Dati!F6) -> 0.5 | K6: =IF(OR(H6="",J6=""),"",IF(H6*J6=0,"",H6*J6)) -> 17.04 | L6: =IF(A6="","",IFERROR(IF(SUMPRODUCT((ISNUMBER(A$2:A6))*(A$2:A6>1000)*(MONTH(IF(ISNUMBER(A$2:A6),A$2:A6,1))=MONTH(A6))*(YEAR(IF(ISNUMBER(A$2:A6),A$2:A6,1))=YEAR(A6))*IF(ISNUMBER(K$2:K6),K$2:K6,0))=0,"",SUMPRODUCT((ISNUMBER(A$2:A6))*(A$2:A6>1000)*(MONTH(IF(ISNUMBER(A$2:A6),A$2:A6,1))=MONTH(A6))*(YEAR(IF(ISNUMBER(A$2:A6),A$2:A6,1))=YEAR(A6))*IF(ISNUMBER(K$2:K6),K$2:K6,0))),"")) -> 81.720726 | M6: =IF(A6="","",IFERROR(IF(SUMIF(N$2:N6,"CASA",K$2:K6)=0,"",SUMIF(N$2:N6,"CASA",K$2:K6)),"")) | N6: =IF(J6="","",IF(J6=0.2,"CASA",IF(Dati!G6="","",Dati!G6))) -> EVDC
A7: =IF(Dati!A7="","",Dati!A7) -> 46107 | B7: =IF(Dati!B7="","",Dati!B7) -> 1293 | C7: =IF(B7="","",IF(ISNUMBER(B6),IF(B7-B6<0,B7,IF(B7-B6=0,"",B7-B6)),B7)) -> 163 | D7: =IF(Dati!C7="","",IF(Dati!C7>1,Dati!C7/100,Dati!C7)) -> 0.38 | E7: =IF(Dati!D7="","",IF(Dati!D7>1,Dati!D7/100,Dati!D7)) -> 0.76 | F7: =IF(OR(D7="",E7=""),"",IF(OR(D7>1,E7>1),(E7-D7)/100,E7-D7)) -> 0.38 | G7: =IF(F7="","",IF(64*F7=0,"",64*F7)) -> 24.32 | H7: =IF(Dati!E7="","",Dati!E7) -> 23.79 | I7: =IFERROR(IF(OR(C7="",C7=0),"",H7/C7*100),"") -> 14.595092 | J7: =IF(Dati!F7="","",Dati!F7) -> 0.2 | K7: =IF(OR(H7="",J7=""),"",IF(H7*J7=0,"",H7*J7)) -> 4.758 | L7: =IF(A7="","",IFERROR(IF(SUMPRODUCT((ISNUMBER(A$2:A7))*(A$2:A7>1000)*(MONTH(IF(ISNUMBER(A$2:A7),A$2:A7,1))=MONTH(A7))*(YEAR(IF(ISNUMBER(A$2:A7),A$2:A7,1))=YEAR(A7))*IF(ISNUMBER(K$2:K7),K$2:K7,0))=0,"",SUMPRODUCT((ISNUMBER(A$2:A7))*(A$2:A7>1000)*(MONTH(IF(ISNUMBER(A$2:A7),A$2:A7,1))=MONTH(A7))*(YEAR(IF(ISNUMBER(A$2:A7),A$2:A7,1))=YEAR(A7))*IF(ISNUMBER(K$2:K7),K$2:K7,0))),"")) -> 86.478726 | M7: =IF(A7="","",IFERROR(IF(SUMIF(N$2:N7,"CASA",K$2:K7)=0,"",SUMIF(N$2:N7,"CASA",K$2:K7)),"")) -> 4.758 | N7: =IF(J7="","",IF(J7=0.2,"CASA",IF(Dati!G7="","",Dati!G7))) -> CASA
A8: =IF(Dati!A8="","",Dati!A8) -> 46111 | B8: =IF(Dati!B8="","",Dati!B8) -> 1400 | C8: =IF(B8="","",IF(ISNUMBER(B7),IF(B8-B7<0,B8,IF(B8-B7=0,"",B8-B7)),B8)) -> 107 | D8: =IF(Dati!C8="","",IF(Dati!C8>1,Dati!C8/100,Dati!C8)) -> 0.44 | E8: =IF(Dati!D8="","",IF(Dati!D8>1,Dati!D8/100,Dati!D8)) -> 0.8 | F8: =IF(OR(D8="",E8=""),"",IF(OR(D8>1,E8>1),(E8-D8)/100,E8-D8)) -> 0.36 | G8: =IF(F8="","",IF(64*F8=0,"",64*F8)) -> 23.04 | H8: =IF(Dati!E8="","",Dati!E8) -> 24.04 | I8: =IFERROR(IF(OR(C8="",C8=0),"",H8/C8*100),"") -> 22.46729 | J8: =IF(Dati!F8="","",Dati!F8) -> 0.2 | K8: =IF(OR(H8="",J8=""),"",IF(H8*J8=0,"",H8*J8)) -> 4.808 | L8: =IF(A8="","",IFERROR(IF(SUMPRODUCT((ISNUMBER(A$2:A8))*(A$2:A8>1000)*(MONTH(IF(ISNUMBER(A$2:A8),A$2:A8,1))=MONTH(A8))*(YEAR(IF(ISNUMBER(A$2:A8),A$2:A8,1))=YEAR(A8))*IF(ISNUMBER(K$2:K8),K$2:K8,0))=0,"",SUMPRODUCT((ISNUMBER(A$2:A8))*(A$2:A8>1000)*(MONTH(IF(ISNUMBER(A$2:A8),A$2:A8,1))=MONTH(A8))*(YEAR(IF(ISNUMBER(A$2:A8),A$2:A8,1))=YEAR(A8))*IF(ISNUMBER(K$2:K8),K$2:K8,0))),"")) -> 91.286726 | M8: =IF(A8="","",IFERROR(IF(SUMIF(N$2:N8,"CASA",K$2:K8)=0,"",SUMIF(N$2:N8,"CASA",K$2:K8)),"")) -> 9.566 | N8: =IF(J8="","",IF(J8=0.2,"CASA",IF(Dati!G8="","",Dati!G8))) -> CASA
A9: =IF(Dati!A9="","",Dati!A9) -> 46113 | B9: =IF(Dati!B9="","",Dati!B9) -> 1543 | C9: =IF(B9="","",IF(ISNUMBER(B8),IF(B9-B8<0,B9,IF(B9-B8=0,"",B9-B8)),B9)) -> 143 | D9: =IF(Dati!C9="","",IF(Dati!C9>1,Dati!C9/100,Dati!C9)) -> 0.34 | E9: =IF(Dati!D9="","",IF(Dati!D9>1,Dati!D9/100,Dati!D9)) -> 0.8 | F9: =IF(OR(D9="",E9=""),"",IF(OR(D9>1,E9>1),(E9-D9)/100,E9-D9)) -> 0.46 | G9: =IF(F9="","",IF(64*F9=0,"",64*F9)) -> 29.44 | H9: =IF(Dati!E9="","",Dati!E9) -> 30.56 | I9: =IFERROR(IF(OR(C9="",C9=0),"",H9/C9*100),"") -> 21.370629 | J9: =IF(Dati!F9="","",Dati!F9) -> 0.2 | K9: =IF(OR(H9="",J9=""),"",IF(H9*J9=0,"",H9*J9)) -> 6.112 | L9: =IF(A9="","",IFERROR(IF(SUMPRODUCT((ISNUMBER(A$2:A9))*(A$2:A9>1000)*(MONTH(IF(ISNUMBER(A$2:A9),A$2:A9,1))=MONTH(A9))*(YEAR(IF(ISNUMBER(A$2:A9),A$2:A9,1))=YEAR(A9))*IF(ISNUMBER(K$2:K9),K$2:K9,0))=0,"",SUMPRODUCT((ISNUMBER(A$2:A9))*(A$2:A9>1000)*(MONTH(IF(ISNUMBER(A$2:A9),A$2:A9,1))=MONTH(A9))*(YEAR(IF(ISNUMBER(A$2:A9),A$2:A9,1))=YEAR(A9))*IF(ISNUMBER(K$2:K9),K$2:K9,0))),"")) -> 6.112 | M9: =IF(A9="","",IFERROR(IF(SUMIF(N$2:N9,"CASA",K$2:K9)=0,"",SUMIF(N$2:N9,"CASA",K$2:K9)),"")) -> 15.678 | N9: =IF(J9="","",IF(J9=0.2,"CASA",IF(Dati!G9="","",Dati!G9))) -> CASA
A10: =IF(Dati!A10="","",Dati!A10) -> 46117 | B10: =IF(Dati!B10="","",Dati!B10) -> 1717 | C10: =IF(B10="","",IF(ISNUMBER(B9),IF(B10-B9<0,B10,IF(B10-B9=0,"",B10-B9)),B10)) -> 174 | D10: =IF(Dati!C10="","",IF(Dati!C10>1,Dati!C10/100,Dati!C10)) -> 0.33 | E10: =IF(Dati!D10="","",IF(Dati!D10>1,Dati!D10/100,Dati!D10)) -> 0.67 | F10: =IF(OR(D10="",E10=""),"",IF(OR(D10>1,E10>1),(E10-D10)/100,E10-D10)) -> 0.34 | G10: =IF(F10="","",IF(64*F10=0,"",64*F10)) -> 21.76 | H10: =IF(Dati!E10="","",Dati!E10) -> 20.976 | I10: =IFERROR(IF(OR(C10="",C10=0),"",H10/C10*100),"") -> 12.055172 | J10: =IF(Dati!F10="","",Dati!F10) -> 0.2 | K10: =IF(OR(H10="",J10=""),"",IF(H10*J10=0,"",H10*J10)) -> 4.1952 | L10: =IF(A10="","",IFERROR(IF(SUMPRODUCT((ISNUMBER(A$2:A10))*(A$2:A10>1000)*(MONTH(IF(ISNUMBER(A$2:A10),A$2:A10,1))=MONTH(A10))*(YEAR(IF(ISNUMBER(A$2:A10),A$2:A10,1))=YEAR(A10))*IF(ISNUMBER(K$2:K10),K$2:K10,0))=0,"",SUMPRODUCT((ISNUMBER(A$2:A10))*(A$2:A10>1000)*(MONTH(IF(ISNUMBER(A$2:A10),A$2:A10,1))=MONTH(A10))*(YEAR(IF(ISNUMBER(A$2:A10),A$2:A10,1))=YEAR(A10))*IF(ISNUMBER(K$2:K10),K$2:K10,0))),"")) -> 10.3072 | M10: =IF(A10="","",IFERROR(IF(SUMIF(N$2:N10,"CASA",K$2:K10)=0,"",SUMIF(N$2:N10,"CASA",K$2:K10)),"")) -> 19.8732 | N10: =IF(J10="","",IF(J10=0.2,"CASA",IF(Dati!G10="","",Dati!G10))) -> CASA
A11: =IF(Dati!A11="","",Dati!A11) -> 46117 | B11: =IF(Dati!B11="","",Dati!B11) -> 1792 | C11: =IF(B11="","",IF(ISNUMBER(B10),IF(B11-B10<0,B11,IF(B11-B10=0,"",B11-B10)),B11)) -> 75 | D11: =IF(Dati!C11="","",IF(Dati!C11>1,Dati!C11/100,Dati!C11)) -> 0.41 | E11: =IF(Dati!D11="","",IF(Dati!D11>1,Dati!D11/100,Dati!D11)) -> 0.8 | F11: =IF(OR(D11="",E11=""),"",IF(OR(D11>1,E11>1),(E11-D11)/100,E11-D11)) -> 0.39 | G11: =IF(F11="","",IF(64*F11=0,"",64*F11)) -> 24.96 | H11: =IF(Dati!E11="","",Dati!E11) -> 25.307 | I11: =IFERROR(IF(OR(C11="",C11=0),"",H11/C11*100),"") -> 33.742667 | J11: =IF(Dati!F11="","",Dati!F11) -> 0.2 | K11: =IF(OR(H11="",J11=""),"",IF(H11*J11=0,"",H11*J11)) -> 5.0614 | L11: =IF(A11="","",IFERROR(IF(SUMPRODUCT((ISNUMBER(A$2:A11))*(A$2:A11>1000)*(MONTH(IF(ISNUMBER(A$2:A11),A$2:A11,1))=MONTH(A11))*(YEAR(IF(ISNUMBER(A$2:A11),A$2:A11,1))=YEAR(A11))*IF(ISNUMBER(K$2:K11),K$2:K11,0))=0,"",SUMPRODUCT((ISNUMBER(A$2:A11))*(A$2:A11>1000)*(MONTH(IF(ISNUMBER(A$2:A11),A$2:A11,1))=MONTH(A11))*(YEAR(IF(ISNUMBER(A$2:A11),A$2:A11,1))=YEAR(A11))*IF(ISNUMBER(K$2:K11),K$2:K11,0))),"")) -> 15.3686 | M11: =IF(A11="","",IFERROR(IF(SUMIF(N$2:N11,"CASA",K$2:K11)=0,"",SUMIF(N$2:N11,"CASA",K$2:K11)),"")) -> 24.9346 | N11: =IF(J11="","",IF(J11=0.2,"CASA",IF(Dati!G11="","",Dati!G11))) -> CASA
A12: =IF(Dati!A12="","",Dati!A12) -> 46119 | B12: =IF(Dati!B12="","",Dati!B12) -> 1926 | C12: =IF(B12="","",IF(ISNUMBER(B11),IF(B12-B11<0,B12,IF(B12-B11=0,"",B12-B11)),B12)) -> 134 | D12: =IF(Dati!C12="","",IF(Dati!C12>1,Dati!C12/100,Dati!C12)) -> 0.49 | E12: =IF(Dati!D12="","",IF(Dati!D12>1,Dati!D12/100,Dati!D12)) -> 0.8 | F12: =IF(OR(D12="",E12=""),"",IF(OR(D12>1,E12>1),(E12-D12)/100,E12-D12)) -> 0.31 | G12: =IF(F12="","",IF(64*F12=0,"",64*F12)) -> 19.84 | H12: =IF(Dati!E12="","",Dati!E12) -> 21.393 | I12: =IFERROR(IF(OR(C12="",C12=0),"",H12/C12*100),"") -> 15.964925 | J12: =IF(Dati!F12="","",Dati!F12) -> 0.2 | K12: =IF(OR(H12="",J12=""),"",IF(H12*J12=0,"",H12*J12)) -> 4.2786 | L12: =IF(A12="","",IFERROR(IF(SUMPRODUCT((ISNUMBER(A$2:A12))*(A$2:A12>1000)*(MONTH(IF(ISNUMBER(A$2:A12),A$2:A12,1))=MONTH(A12))*(YEAR(IF(ISNUMBER(A$2:A12),A$2:A12,1))=YEAR(A12))*IF(ISNUMBER(K$2:K12),K$2:K12,0))=0,"",SUMPRODUCT((ISNUMBER(A$2:A12))*(A$2:A12>1000)*(MONTH(IF(ISNUMBER(A$2:A12),A$2:A12,1))=MONTH(A12))*(YEAR(IF(ISNUMBER(A$2:A12),A$2:A12,1))=YEAR(A12))*IF(ISNUMBER(K$2:K12),K$2:K12,0))),"")) -> 19.6472 | M12: =IF(A12="","",IFERROR(IF(SUMIF(N$2:N12,"CASA",K$2:K12)=0,"",SUMIF(N$2:N12,"CASA",K$2:K12)),"")) -> 29.2132 | N12: =IF(J12="","",IF(J12=0.2,"CASA",IF(Dati!G12="","",Dati!G12))) -> CASA
A13: =IF(Dati!A13="","",Dati!A13) -> 46122 | B13: =IF(Dati!B13="","",Dati!B13) -> 2075 | C13: =IF(B13="","",IF(ISNUMBER(B12),IF(B13-B12<0,B13,IF(B13-B12=0,"",B13-B12)),B13)) -> 149 | D13: =IF(Dati!C13="","",IF(Dati!C13>1,Dati!C13/100,Dati!C13)) -> 0.43 | E13: =IF(Dati!D13="","",IF(Dati!D13>1,Dati!D13/100,Dati!D13)) -> 0.8 | F13: =IF(OR(D13="",E13=""),"",IF(OR(D13>1,E13>1),(E13-D13)/100,E13-D13)) -> 0.37 | G13: =IF(F13="","",IF(64*F13=0,"",64*F13)) -> 23.68 | H13: =IF(Dati!E13="","",Dati!E13) -> 24.82 | I13: =IFERROR(IF(OR(C13="",C13=0),"",H13/C13*100),"") -> 16.657718 | J13: =IF(Dati!F13="","",Dati!F13) -> 0.2 | K13: =IF(OR(H13="",J13=""),"",IF(H13*J13=0,"",H13*J13)) -> 4.964 | L13: =IF(A13="","",IFERROR(IF(SUMPRODUCT((ISNUMBER(A$2:A13))*(A$2:A13>1000)*(MONTH(IF(ISNUMBER(A$2:A13),A$2:A13,1))=MONTH(A13))*(YEAR(IF(ISNUMBER(A$2:A13),A$2:A13,1))=YEAR(A13))*IF(ISNUMBER(K$2:K13),K$2:K13,0))=0,"",SUMPRODUCT((ISNUMBER(A$2:A13))*(A$2:A13>1000)*(MONTH(IF(ISNUMBER(A$2:A13),A$2:A13,1))=MONTH(A13))*(YEAR(IF(ISNUMBER(A$2:A13),A$2:A13,1))=YEAR(A13))*IF(ISNUMBER(K$2:K13),K$2:K13,0))),"")) -> 24.6112 | M13: =IF(A13="","",IFERROR(IF(SUMIF(N$2:N13,"CASA",K$2:K13)=0,"",SUMIF(N$2:N13,"CASA",K$2:K13)),"")) -> 34.1772 | N13: =IF(J13="","",IF(J13=0.2,"CASA",IF(Dati!G13="","",Dati!G13))) -> CASA
A14: =IF(Dati!A14="","",Dati!A14) -> 46127 | B14: =IF(Dati!B14="","",Dati!B14) -> 2277 | C14: =IF(B14="","",IF(ISNUMBER(B13),IF(B14-B13<0,B14,IF(B14-B13=0,"",B14-B13)),B14)) -> 202 | D14: =IF(Dati!C14="","",IF(Dati!C14>1,Dati!C14/100,Dati!C14)) -> 0.22 | E14: =IF(Dati!D14="","",IF(Dati!D14>1,Dati!D14/100,Dati!D14)) -> 0.64 | F14: =IF(OR(D14="",E14=""),"",IF(OR(D14>1,E14>1),(E14-D14)/100,E14-D14)) -> 0.42 | G14: =IF(F14="","",IF(64*F14=0,"",64*F14)) -> 26.88 | H14: =IF(Dati!E14="","",Dati!E14) -> 26.02 | I14: =IFERROR(IF(OR(C14="",C14=0),"",H14/C14*100),"") -> 12.881188 | J14: =IF(Dati!F14="","",Dati!F14) -> 0.2 | K14: =IF(OR(H14="",J14=""),"",IF(H14*J14=0,"",H14*J14)) -> 5.204 | L14: =IF(A14="","",IFERROR(IF(SUMPRODUCT((ISNUMBER(A$2:A14))*(A$2:A14>1000)*(MONTH(IF(ISNUMBER(A$2:A14),A$2:A14,1))=MONTH(A14))*(YEAR(IF(ISNUMBER(A$2:A14),A$2:A14,1))=YEAR(A14))*IF(ISNUMBER(K$2:K14),K$2:K14,0))=0,"",SUMPRODUCT((ISNUMBER(A$2:A14))*(A$2:A14>1000)*(MONTH(IF(ISNUMBER(A$2:A14),A$2:A14,1))=MONTH(A14))*(YEAR(IF(ISNUMBER(A$2:A14),A$2:A14,1))=YEAR(A14))*IF(ISNUMBER(K$2:K14),K$2:K14,0))),"")) -> 29.8152 | M14: =IF(A14="","",IFERROR(IF(SUMIF(N$2:N14,"CASA",K$2:K14)=0,"",SUMIF(N$2:N14,"CASA",K$2:K14)),"")) -> 39.3812 | N14: =IF(J14="","",IF(J14=0.2,"CASA",IF(Dati!G14="","",Dati!G14))) -> CASA
... A1001: =IF(Dati!A1001="","",Dati!A1001) | B1001: =IF(Dati!B1001="","",Dati!B1001) | C1001: =IF(B1001="","",IF(ISNUMBER(B1000),IF(B1001-B1000<0,B1001,IF(B1001-B1000=0,"",B1001-B1000)),B1001)) | D1001: =IF(Dati!C1001="","",IF(Dati!C1001>1,Dati!C1001/100,Dati!C1001)) | E1001: =IF(Dati!D1001="","",IF(Dati!D1001>1,Dati!D1001/100,Dati!D1001)) | F1001: =IF(OR(D1001="",E1001=""),"",IF(OR(D1001>1,E1001>1),(E1001-D1001)/100,E1001-D1001)) | G1001: =IF(F1001="","",IF(64*F1001=0,"",64*F1001)) | H1001: =IF(Dati!E1001="","",Dati!E1001) | I1001: =IFERROR(IF(OR(C1001="",C1001=0),"",H1001/C1001*100),"") | J1001: =IF(Dati!F1001="","",Dati!F1001) | K1001: =IF(OR(H1001="",J1001=""),"",IF(H1001*J1001=0,"",H1001*J1001)) | L1001: =IF(A1001="","",IFERROR(IF(SUMPRODUCT((ISNUMBER(A$2:A1001))*(A$2:A1001>1000)*(MONTH(IF(ISNUMBER(A$2:A1001),A$2:A1001,1))=MONTH(A1001))*(YEAR(IF(ISNUMBER(A$2:A1001),A$2:A1001,1))=YEAR(A1001))*IF(ISNUMBER(K$2:K1001),K$2:K1001,0))=0,"",SUMPRODUCT((ISNUMBER(A$2:A1001))*(A$2:A1001>1000)*(MONTH(IF(ISNUMBER(A$2:A1001),A$2:A1001,1))=MONTH(A1001))*(YEAR(IF(ISNUMBER(A$2:A1001),A$2:A1001,1))=YEAR(A1001))*IF(ISNUMBER(K$2:K1001),K$2:K1001,0))),"")) | M1001: =IF(A1001="","",IFERROR(IF(SUMIF(N$2:N1001,"CASA",K$2:K1001)=0,"",SUMIF(N$2:N1001,"CASA",K$2:K1001)),"")) | N1001: =IF(J1001="","",IF(J1001=0.2,"CASA",IF(Dati!G1001="","",Dati!G1001)))

Sheet Dati
A1: DATA | B1: KM TOTALI | C1: % PRIMA DELLA CARICA | D1: % DOPO LA CARICA | E1: KWh EFFETTIVI | F1: PREZZO/ KWh | G1: DOVE
A2: 46080 | B2: 286 | C2: 0.26 | D2: 0.86 | E2: 39.34 | F2: 0.5 | G2: EVDC
A3: 46085 | B3: 533 | C3: 0.14 | D3: 0.86 | E3: 46.156 | F3: 0.5 | G3: EVDC
A4: 46092 | B4: 758 | C4: 0.18 | D4: 0.8 | E4: 40.374 | F4: 0.649 | G4: next charge
A5: 46096 | B5: 926 | C5: 0.37 | D5: 0.85 | E5: 30.8 | F5: 0.5 | G5: EVDC
A6: 46101 | B6: 1130 | C6: 0.3 | D6: 0.84 | E6: 34.08 | F6: 0.5 | G6: EVDC
A7: 46107 | B7: 1293 | C7: 0.38 | D7: 0.76 | E7: 23.79 | F7: 0.2
A8: 46111 | B8: 1400 | C8: 0.44 | D8: 0.8 | E8: 24.04 | F8: 0.2
A9: 46113 | B9: 1543 | C9: 0.34 | D9: 0.8 | E9: 30.56 | F9: 0.2
A10: 46117 | B10: 1717 | C10: 0.33 | D10: 0.67 | E10: 20.976 | F10: 0.2
A11: 46117 | B11: 1792 | C11: 0.41 | D11: 0.8 | E11: 25.307 | F11: 0.2
A12: 46119 | B12: 1926 | C12: 0.49 | D12: 0.8 | E12: 21.393 | F12: 0.2
A13: 46122 | B13: 2075 | C13: 0.43 | D13: 0.8 | E13: 24.82 | F13: 0.2
A14: 46127 | B14: 2277 | C14: 0.22 | D14: 0.64 | E14: 26.02 | F14: 0.2
A15: 46128 | B15: 2326 | C15: 0.51 | D15: 0.7 | E15: 12.73 | F15: 0.2
A16: 46130 | B16: 2414 | C16: 0.45 | D16: 0.8 | E16: 23.29 | F16: 0.2
A17: 46133 | B17: 2592 | C17: 0.33 | D17: 0.75 | E17: 26.32 | F17: 0.2
A18: 46135 | B18: 2720 | C18: 0.42 | D18: 0.78 | E18: 22.72 | F18: 0.2
... A24: 46156 | B24: 3615 | C24: 0.36 | D24: 0.8 | E24: 29.17 | F24: 0.2
A25: 46161 | B25: 3814 | C25: 0.17 | D25: 0.42 | E25: 16.37 | F25: 0.61 | G25: ENEL X POMIGLIANO
A26: 46161 | B26: 3869 | C26: 0.3 | D26: 0.8 | E26: 33.07 | F26: 0.2
